Workbook

Sheet Trip_Data 
A1: Trip_ID | B1: Vehicle_ID | C1: Driver_ID | D1: Origin | E1: Destination | F1: Distance_km | G1: Fuel_Consumed_L | H1: Delivery_Status | I1: Delivery_Date
A2: T001 | B2: V04 | C2: D01 | D2: Delhi | E2: Pune | F2: 1173 | G2: 108.42 | H2: On-Time | I2: 44953
A3: T002 | B3: V06 | C3: D08 | D3: Mumbai | E3: Bangalore | F3: 1727 | G3: 161.33 | H3: On-Time | I3: 44978
A4: T003 | B4: V06 | C4: D08 | D4: Mumbai | E4: Pune | F4: 1459 | G4: 154.7 | H4: On-Time | I4: 44974
A5: T004 | B5: V04 | C5: D09 | D5: Hyderabad | E5: Pune | F5: 382 | G5: 26.6 | H5: On-Time | I5: 44975
A6: T005 | B6: V06 | C6: D08 | D6: Pune | E6: Mumbai | F6: 398 | G6: 33.2 | H6: On-Time | I6: 44972
A7: T006 | B7: V06 | C7: D07 | D7: Chennai | E7: Mumbai | F7: 1275 | G7: 85.04 | H7: Late | I7: 44982
A8: T007 | B8: V07 | C8: D03 | D8: Chennai | E8: Kolkata | F8: 752 | G8: 58.08 | H8: On-Time | I8: 44945
A9: T008 | B9: V02 | C9: D10 | D9: Delhi | E9: Pune | F9: 74 | G9: 5.24 | H9: On-Time | I9: 44927
A10: T009 | B10: V02 | C10: D07 | D10: Delhi | E10: Hyderabad | F10: 186 | G10: 16.22 | H10: On-Time | I10: 44980
A11: T010 | B11: V02 | C11: D02 | D11: Bangalore | E11: Hyderabad | F11: 1375 | G11: 105.21 | H11: Late | I11: 44959
A12: T011 | B12: V06 | C12: D03 | D12: Kolkata | E12: Hyderabad | F12: 419 | G12: 31.17 | H12: On-Time | I12: 44947
A13: T012 | B13: V06 | C13: D01 | D13: Kolkata | E13: Delhi | F13: 751 | G13: 51.77 | H13: On-Time | I13: 44972
... A16: T015 | B16: V05 | C16: D06 | D16: Kolkata | E16: Mumbai | F16: 1956 | G16: 179.88 | H16: On-Time | I16: 44947
A17: T016 | B17: V05 | C17: D06 | D17: Bangalore | E17: Mumbai | F17: 858 | H17: Late | I17: 44944
A18: T017 | B18: V07 | C18: D07 | D18: Pune | E18: Kolkata | F18: 1269 | G18: 102.91 | H18: On-Time | I18: 44942
A19: T018 | B19: V07 | C19: D10 | D19: Pune | E19: Delhi | F19: 1565 | G19: 107.23 | H19: On-Time | I19: 44969
A20: T019 | B20: V07 | C20: D10 | D20: Hyderabad | E20: Pune | F20: 1796 | G20: 155.52 | H20: On-Time | I20: 44985
A21: T020 | B21: V04 | C21: D02 | D21: Mumbai | E21: Bangalore | F21: 1640 | G21: 148.87 | H21: On-Time | I21: 44932
A22: T021 | B22: V07 | C22: D07 | D22: Delhi | E22: Mumbai | F22: 446 | G22: 31.98 | H22: Late | I22: 44937
A23: T022 | B23: V07 | C23: D09 | D23: Hyderabad | E23: Delhi | F23: 140 | G23: 11.44 | H23: On-Time | I23: 44964
A24: T023 | B24: V06 | C24: D04 | D24: Chennai | E24: Delhi | F24: 1729 | G24: 197.55 | H24: On-Time | I24: 44963
A25: T024 | B25: V04 | C25: D01 | D25: Kolkata | E25: Mumbai | F25: 1376 | G25: 96.63 | H25: On-Time | I25: 44971
A26: T025 | B26: V04 | C26: D02 | D26: Bangalore | E26: Chennai | F26: 1721 | G26: 120.65 | H26: Late | I26: 44963
A27: T026 | B27: V05 | C27: D04 | D27: Chennai | E27: Pune | F27: 1784 | H27: Late | I27: 44943
A28: T027 | B28: V06 | C28: D07 | D28: Pune | E28: Kolkata | F28: 1007 | G28: 116.6 | H28: Late | I28: 44974
A29: T028 | B29: V05 | C29: D06 | D29: Pune | E29: Bangalore | F29: 1903 | G29: 151.18 | H29: Late | I29: 44977
A30: T029 | B30: V01 | C30: D06 | D30: Mumbai | E30: Bangalore | F30: 1262 | G30: 100.72 | H30: On-Time | I30: 44954
A31: T030 | B31: V02 | C31: D09 | D31: Kolkata | E31: Hyderabad | F31: 317 | G31: 28.83 | H31: On-Time | I31: 44985
A32: T031 | B32: V05 | C32: D04 | D32: Hyderabad | E32: Delhi | F32: 1188 | G32: 92.84 | H32: On-Time | I32: 44960
A33: T032 | B33: V01 | C33: D10 | D33: Hyderabad | E33: Kolkata | F33: 398 | G33: 43.89 | H33: Late | I33: 44962
A34: T033 | B34: V05 | C34: D09 | D34: Hyderabad | E34: Chennai | F34: 385 | G34: 31.03 | H34: Late | I34: 44950
A35: T034 | B35: V02 | C35: D10 | D35: Delhi | E35: Hyderabad | F35: 818 | G35: 94.24 | H35: Late | I35: 44975
A36: T035 | B36: V04 | C36: D04 | D36: Delhi | E36: Kolkata | F36: 1806 | G36: 121.36 | H36: On-Time | I36: 44967
A37: T036 | B37: V02 | C37: D10 | D37: Delhi | E37: Pune | F37: 424 | G37: 37.63 | H37: On-Time | I37: 44975
A38: T037 | B38: V06 | C38: D01 | D38: Delhi | E38: Bangalore | F38: 909 | G38: 70.4 | H38: On-Time | I38: 44944
A39: T038 | B39: V03 | C39: D06 | D39: Bangalore | E39: Mumbai | F39: 1404 | G39: 151.36 | H39: Late | I39: 44981
... A44: T043 | B44: V06 | C44: D06 | D44: Hyderabad | E44: Bangalore | F44: 116 | G44: 8.71 | H44: Late | I44: 44932
A45: T044 | B45: V04 | C45: D07 | D45: Delhi | E45: Mumbai | F45: 1259 | H45: Late | I45: 44955
A46: T045 | B46: V02 | C46: D03 | D46: Kolkata | E46: Chennai | F46: 1803 | G46: 211.34 | H46: On-Time | I46: 44970
...

Sheet Vehicle_Master 
A1: Vehicle_ID | B1: Vehicle_Type | C1: Capacity_kg | D1: Maintenance_Cost
A2: V01 | B2: Van | C2: 8424 | D2: 5633
A3: V02 | B3: Truck | C3: 1970 | D3: 6776
A4: V03 | B4: Truck | C4: 1207 | D4: 18031
A5: V04 | B5: Mini-Truck | C5: 8803 | D5: 9033
A6: V05 | B6: Truck | C6: 9941 | D6: 17751
A7: V06 | B7: Van | C7: 6053 | D7: 5914
A8: V07 | B8: Van | C8: 2598 | D8: 12837

Sheet README
A1: Fleet Performance & Delivery Efficiency - Excel Workbook
A3: Sheets
A4: Trip_Data | B4: Original 9 columns (untouched) + 7 calculated columns (J-P). Yellow cells in column G are the 3 missing fuel values (T016, T026, T044).
A5: Vehicle_Master | B5: The 7 vehicles: type, capacity, maintenance cost.
A6: Assumptions | B6: Mean fuel used for imputation (formula) and fuel cost per trip = 100 (input, yellow).
A7: Analysis | B7: KPIs and summary tables, all formulas. Includes manual checks of what might influence late deliveries.
A8: Dashboard | B8: KPI tiles and 4 charts.
A10: Cleaning done
A11: 1 | B11: Missing Fuel_Consumed_L replaced by the mean of the other 47 trips (91.88 L), in column J. Column G keeps the original.
A12: 2 | B12: Vehicle_ID checked: every trip matches a vehicle in Vehicle_Master. No duplicate Trip_IDs, no zero distances.
A13: 3 | B13: Vehicle_Type and Maintenance_Cost are looked up from Vehicle_Master using Vehicle_ID (the Excel version of the Power BI relationship).
A15: Formulas used
A16: Fuel Efficiency | B16: Distance / Fuel. Per trip in column N; overall = total km / total litres (Analysis B7).
A17: On-Time Delivery % | B17: On-Time trips / Total trips.
A18: Cost per km | B18: (Fuel cost 100 + Maintenance Cost) / Distance, per trip in column O; card = average of all trips.
A20: Assumptions and limits
A21: A | B21: Fuel cost = 100 is treated as a flat amount per trip. Change it on the Assumptions sheet.
A22: B | B22: Avg. Delivery Time cannot be calculated: the dataset has no time or duration column.
A23: C | B23: Only 50 trips: patterns in the late-delivery checks are indicative, not statistically strong.

Sheet Dashboard
A1: Fleet Performance & Delivery Efficiency Dashboard
A2: Logistics trips, Jan-Feb 2023 | 50 trips, 7 vehicles, 10 drivers
A4: On-Time Delivery % | D4: Fuel Efficiency (km/L) | G4: Average Cost per km | J4: Total Trips
A5: =Analysis!B6 -> 0.6 | D5: =Analysis!B7 -> 11.523571 | G5: =Analysis!B8 -> 18.034176 | J5: =Analysis!B4 -> 50
A41: Avg. Delivery Time card: the dataset has no delivery-time column, so it is not shown. See README.

Sheet Analysis
A1: Analysis
A3: KPI | B3: Value | H3: Fuel Efficiency by Month
A4: Total Trips | B4: =COUNTA(Trip_Data!$A$2:$A$51) -> 50 | H4: Month Start | I4: Month End | J4: Fuel Efficiency (km/L)
A5: On-Time Trips | B5: =SUM(Trip_Data!$P$2:$P$51) -> 30 | H5: 44927 | I5: 44957 | J5: =SUMIFS(Trip_Data!$F$2:$F$51,Trip_Data!$I$2:$I$51,">="&H5,Trip_Data!$I$2:$I$51,"<="&I5)/SUMIFS(Trip_Data!$J$2:$J$51,Trip_Data!$I$2:$I$51,">="&H5,Trip_Data!$I$2:$I$51,"<="&I5) -> 11.772002
A6: On-Time Delivery % | B6: =B5/B4 -> 0.6 | H6: 44958 | I6: 44985 | J6: =SUMIFS(Trip_Data!$F$2:$F$51,Trip_Data!$I$2:$I$51,">="&H6,Trip_Data!$I$2:$I$51,"<="&I6)/SUMIFS(Trip_Data!$J$2:$J$51,Trip_Data!$I$2:$I$51,">="&H6,Trip_Data!$I$2:$I$51,"<="&I6) -> 11.394119
A7: Fuel Efficiency (km/L) = total km / total litres | B7: =SUM(Trip_Data!$F$2:$F$51)/SUM(Trip_Data!$J$2:$J$51) -> 11.523571
A8: Average Cost per km | B8: =AVERAGE(Trip_Data!$O$2:$O$51) -> 18.034176
A9: Avg. Delivery Time | B9: Not in dataset (no time column) - ask mentor | H9: Fuel Efficiency Trend by Delivery Date
H10: Delivery Date | I10: Distance (km) | J10: Fuel (L) | K10: Fuel Efficiency (km/L)
A11: On-Time Delivery % by Destination | H11: 44927 | I11: =SUMIFS(Trip_Data!$F$2:$F$51,Trip_Data!$I$2:$I$51,H11) -> 74 | J11: =SUMIFS(Trip_Data!$J$2:$J$51,Trip_Data!$I$2:$I$51,H11) -> 5.24 | K11: =I11/J11 -> 14.122137
A12: Destination | B12: Total Trips | C12: On-Time Trips | D12: On-Time % | H12: 44932 | I12: =SUMIFS(Trip_Data!$F$2:$F$51,Trip_Data!$I$2:$I$51,H12) -> 1756 | J12: =SUMIFS(Trip_Data!$J$2:$J$51,Trip_Data!$I$2:$I$51,H12) -> 157.58 | K12: =I12/J12 -> 11.143546
A13: Delhi | B13: =COUNTIFS(Trip_Data!$E$2:$E$51,A13) -> 8 | C13: =COUNTIFS(Trip_Data!$E$2:$E$51,A13,Trip_Data!$H$2:$H$51,"On-Time") -> 7 | D13: =C13/B13 -> 0.875 | H13: 44937 | I13: =SUMIFS(Trip_Data!$F$2:$F$51,Trip_Data!$I$2:$I$51,H13) -> 1001 | J13: =SUMIFS(Trip_Data!$J$2:$J$51,Trip_Data!$I$2:$I$51,H13) -> 69.37 | K13: =I13/J13 -> 14.429869
A14: Pune | B14: =COUNTIFS(Trip_Data!$E$2:$E$51,A14) -> 8 | C14: =COUNTIFS(Trip_Data!$E$2:$E$51,A14,Trip_Data!$H$2:$H$51,"On-Time") -> 7 | D14: =C14/B14 -> 0.875 | H14: 44938 | I14: =SUMIFS(Trip_Data!$F$2:$F$51,Trip_Data!$I$2:$I$51,H14) -> 1938 | J14: =SUMIFS(Trip_Data!$J$2:$J$51,Trip_Data!$I$2:$I$51,H14) -> 216.29 | K14: =I14/J14 -> 8.9601923
A15: Bangalore | B15: =COUNTIFS(Trip_Data!$E$2:$E$51,A15) -> 8 | C15: =COUNTIFS(Trip_Data!$E$2:$E$51,A15,Trip_Data!$H$2:$H$51,"On-Time") -> 5 | D15: =C15/B15 -> 0.625 | H15: 44942 | I15: =SUMIFS(Trip_Data!$F$2:$F$51,Trip_Data!$I$2:$I$51,H15) -> 1269 | J15: =SUMIFS(Trip_Data!$J$2:$J$51,Trip_Data!$I$2:$I$51,H15) -> 102.91 | K15: =I15/J15 -> 12.331163
A16: Kolkata | B16: =COUNTIFS(Trip_Data!$E$2:$E$51,A16) -> 6 | C16: =COUNTIFS(Trip_Data!$E$2:$E$51,A16,Trip_Data!$H$2:$H$51,"On-Time") -> 3 | D16: =C16/B16 -> 0.5 | H16: 44943 | I16: =SUMIFS(Trip_Data!$F$2:$F$51,Trip_Data!$I$2:$I$51,H16) -> 1784 | J16: =SUMIFS(Trip_Data!$J$2:$J$51,Trip_Data!$I$2:$I$51,H16) -> 91.882979 | K16: =I16/J16 -> 19.416001
A17: Hyderabad | B17: =COUNTIFS(Trip_Data!$E$2:$E$51,A17) -> 6 | C17: =COUNTIFS(Trip_Data!$E$2:$E$51,A17,Trip_Data!$H$2:$H$51,"On-Time") -> 3 | D17: =C17/B17 -> 0.5 | H17: 44944 | I17: =SUMIFS(Trip_Data!$F$2:$F$51,Trip_Data!$I$2:$I$51,H17) -> 1767 | J17: =SUMIFS(Trip_Data!$J$2:$J$51,Trip_Data!$I$2:$I$51,H17) -> 162.28298 | K17: =I17/J17 -> 10.888388
A18: Chennai | B18: =COUNTIFS(Trip_Data!$E$2:$E$51,A18) -> 5 | C18: =COUNTIFS(Trip_Data!$E$2:$E$51,A18,Trip_Data!$H$2:$H$51,"On-Time") -> 2 | D18: =C18/B18 -> 0.4 | H18: 44945 | I18: =SUMIFS(Trip_Data!$F$2:$F$51,Trip_Data!$I$2:$I$51,H18) -> 752 | J18: =SUMIFS(Trip_Data!$J$2:$J$51,Trip_Data!$I$2:$I$51,H18) -> 58.08 | K18: =I18/J18 -> 12.947658
A19: Mumbai | B19: =COUNTIFS(Trip_Data!$E$2:$E$51,A19) -> 9 | C19: =COUNTIFS(Trip_Data!$E$2:$E$51,A19,Trip_Data!$H$2:$H$51,"On-Time") -> 3 | D19: =C19/B19 -> 0.33333333 | H19: 44947 | I19: =SUMIFS(Trip_Data!$F$2:$F$51,Trip_Data!$I$2:$I$51,H19) -> 3471 | J19: =SUMIFS(Trip_Data!$J$2:$J$51,Trip_Data!$I$2:$I$51,H19) -> 311.57 | K19: =I19/J19 -> 11.140354
H20: 44948 | I20: =SUMIFS(Trip_Data!$F$2:$F$51,Trip_Data!$I$2:$I$51,H20) -> 572 | J20: =SUMIFS(Trip_Data!$J$2:$J$51,Trip_Data!$I$2:$I$51,H20) -> 61.6 | K20: =I20/J20 -> 9.2857143
A21: Cost, Maintenance and Lateness by Vehicle Type | H21: 44950 | I21: =SUMIFS(Trip_Data!$F$2:$F$51,Trip_Data!$I$2:$I$51,H21) -> 385 | J21: =SUMIFS(Trip_Data!$J$2:$J$51,Trip_Data!$I$2:$I$51,H21) -> 31.03 | K21: =I21/J21 -> 12.407348
A22: Vehicle Type | B22: Trips | C22: Avg Cost per km | D22: Avg Maintenance Cost | E22: Late % | H22: 44952 | I22: =SUMIFS(Trip_Data!$F$2:$F$51,Trip_Data!$I$2:$I$51,H22) -> 64 | J22: =SUMIFS(Trip_Data!$J$2:$J$51,Trip_Data!$I$2:$I$51,H22) -> 4.96 | K22: =I22/J22 -> 12.903226
A23: Mini-Truck | B23: =COUNTIFS(Trip_Data!$L$2:$L$51,A23) -> 9 | C23: =AVERAGEIFS(Trip_Data!$O$2:$O$51,Trip_Data!$L$2:$L$51,A23) -> 8.4655158 | D23: =AVERAGEIF(Vehicle_Master!$B$2:$B$8,A23,Vehicle_Master!$D$2:$D$8) -> 9033 | E23: =1-SUMIFS(Trip_Data!$P$2:$P$51,Trip_Data!$L$2:$L$51,A23)/B23 -> 0.44444444 | H23: 44953 | I23: =SUMIFS(Trip_Data!$F$2:$F$51,Trip_Data!$I$2:$I$51,H23) -> 1173 | J23: =SUMIFS(Trip_Data!$J$2:$J$51,Trip_Data!$I$2:$I$51,H23) -> 108.42 | K23: =I23/J23 -> 10.819037
A24: Van | B24: =COUNTIFS(Trip_Data!$L$2:$L$51,A24) -> 22 | C24: =AVERAGEIFS(Trip_Data!$O$2:$O$51,Trip_Data!$L$2:$L$51,A24) -> 18.890421 | D24: =AVERAGEIF(Vehicle_Master!$B$2:$B$8,A24,Vehicle_Master!$D$2:$D$8) -> 8128 | E24: =1-SUMIFS(Trip_Data!$P$2:$P$51,Trip_Data!$L$2:$L$51,A24)/B24 -> 0.36363636 | H24: 44954 | I24: =SUMIFS(Trip_Data!$F$2:$F$51,Trip_Data!$I$2:$I$51,H24) -> 1262 | J24: =SUMIFS(Trip_Data!$J$2:$J$51,Trip_Data!$I$2:$I$51,H24) -> 100.72 | K24: =I24/J24 -> 12.529786
A25: Truck | B25: =COUNTIFS(Trip_Data!$L$2:$L$51,A25) -> 19 | C25: =AVERAGEIFS(Trip_Data!$O$2:$O$51,Trip_Data!$L$2:$L$51,A25) -> 21.575257 | D25: =AVERAGEIF(Vehicle_Master!$B$2:$B$8,A25,Vehicle_Master!$D$2:$D$8) -> 14186 | E25: =1-SUMIFS(Trip_Data!$P$2:$P$51,Trip_Data!$L$2:$L$51,A25)/B25 -> 0.42105263 | H25: 44955 | I25: =SUMIFS(Trip_Data!$F$2:$F$51,Trip_Data!$I$2:$I$51,H25) -> 1259 | J25: =SUMIFS(Trip_Data!$J$2:$J$51,Trip_Data!$I$2:$I$51,H25) -> 91.882979 | K25: =I25/J25 -> 13.702211
H26: 44959 | I26: =SUMIFS(Trip_Data!$F$2:$F$51,Trip_Data!$I$2:$I$51,H26) -> 2946 | J26: =SUMIFS(Trip_Data!$J$2:$J$51,Trip_Data!$I$2:$I$51,H26) -> 293.73 | K26: =I26/J26 -> 10.029619
A27: Late % by Driver (manual "key influencer" check) | H27: 44960 | I27: =SUMIFS(Trip_Data!$F$2:$F$51,Trip_Data!$I$2:$I$51,H27) -> 1188 | J27: =SUMIFS(Trip_Data!$J$2:$J$51,Trip_Data!$I$2:$I$51,H27) -> 92.84 | K27: =I27/J27 -> 12.796209
A28: Driver_ID | B28: Trips | C28: Late Trips | D28: Late % | H28: 44962 | I28: =SUMIFS(Trip_Data!$F$2:$F$51,Trip_Data!$I$2:$I$51,H28) -> 398 | J28: =SUMIFS(Trip_Data!$J$2:$J$51,Trip_Data!$I$2:$I$51,H28) -> 43.89 | K28: =I28/J28 -> 9.0681249
A29: D01 | B29: =COUNTIFS(Trip_Data!$C$2:$C$51,A29) -> 6 | C29: =COUNTIFS(Trip_Data!$C$2:$C$51,A29,Trip_Data!$H$2:$H$51,"Late") -> 2 | D29: =C29/B29 -> 0.33333333 | H29: 44963 | I29: =SUMIFS(Trip_Data!$F$2:$F$51,Trip_Data!$I$2:$I$51,H29) -> 3450 | J29: =SUMIFS(Trip_Data!$J$2:$J$51,Trip_Data!$I$2:$I$51,H29) -> 318.2 | K29: =I29/J29 -> 10.842238
A30: D02 | B30: =COUNTIFS(Trip_Data!$C$2:$C$51,A30) -> 3 | C30: =COUNTIFS(Trip_Data!$C$2:$C$51,A30,Trip_Data!$H$2:$H$51,"Late") -> 2 | D30: =C30/B30 -> 0.66666667 | H30: 44964 | I30: =SUMIFS(Trip_Data!$F$2:$F$51,Trip_Data!$I$2:$I$51,H30) -> 140 | J30: =SUMIFS(Trip_Data!$J$2:$J$51,Trip_Data!$I$2:$I$51,H30) -> 11.44 | K30: =I30/J30 -> 12.237762
A31: D03 | B31: =COUNTIFS(Trip_Data!$C$2:$C$51,A31) -> 6 | C31: =COUNTIFS(Trip_Data!$C$2:$C$51,A31,Trip_Data!$H$2:$H$51,"Late") -> 0 | D31: =C31/B31 -> 0 | H31: 44967 | I31: =SUMIFS(Trip_Data!$F$2:$F$51,Trip_Data!$I$2:$I$51,H31) -> 3051 | J31: =SUMIFS(Trip_Data!$J$2:$J$51,Trip_Data!$I$2:$I$51,H31) -> 216.5 | K31: =I31/J31 -> 14.092379
A32: D04 | B32: =COUNTIFS(Trip_Data!$C$2:$C$51,A32) -> 6 | C32: =COUNTIFS(Trip_Data!$C$2:$C$51,A32,Trip_Data!$H$2:$H$51,"Late") -> 3 | D32: =C32/B32 -> 0.5 | H32: 44969 | I32: =SUMIFS(Trip_Data!$F$2:$F$51,Trip_Data!$I$2:$I$51,H32) -> 1565 | J32: =SUMIFS(Trip_Data!$J$2:$J$51,Trip_Data!$I$2:$I$51,H32) -> 107.23 | K32: =I32/J32 -> 14.594796
A33: D05 | B33: =COUNTIFS(Trip_Data!$C$2:$C$51,A33) -> 1 | C33: =COUNTIFS(Trip_Data!$C$2:$C$51,A33,Trip_Data!$H$2:$H$51,"Late") -> 0 | D33: =C33/B33 -> 0 | H33: 44970 | I33: =SUMIFS(Trip_Data!$F$2:$F$51,Trip_Data!$I$2:$I$51,H33) -> 1803 | J33: =SUMIFS(Trip_Data!$J$2:$J$51,Trip_Data!$I$2:$I$51,H33) -> 211.34 | K33: =I33/J33 -> 8.5312766
A34: D06 | B34: =COUNTIFS(Trip_Data!$C$2:$C$51,A34) -> 7 | C34: =COUNTIFS(Trip_Data!$C$2:$C$51,A34,Trip_Data!$H$2:$H$51,"Late") -> 4 | D34: =C34/B34 -> 0.57142857 | H34: 44971 | I34: =SUMIFS(Trip_Data!$F$2:$F$51,Trip_Data!$I$2:$I$51,H34) -> 1376 | J34: =SUMIFS(Trip_Data!$J$2:$J$51,Trip_Data!$I$2:$I$51,H34) -> 96.63 | K34: =I34/J34 -> 14.239884
A35: D07 | B35: =COUNTIFS(Trip_Data!$C$2:$C$51,A35) -> 7 | C35: =COUNTIFS(Trip_Data!$C$2:$C$51,A35,Trip_Data!$H$2:$H$51,"Late") -> 5 | D35: =C35/B35 -> 0.71428571 | H35: 44972 | I35: =SUMIFS(Trip_Data!$F$2:$F$51,Trip_Data!$I$2:$I$51,H35) -> 1149 | J35: =SUMIFS(Trip_Data!$J$2:$J$51,Trip_Data!$I$2:$I$51,H35) -> 84.97 | K35: =I35/J35 -> 13.52242
A36: D08 | B36: =COUNTIFS(Trip_Data!$C$2:$C$51,A36) -> 4 | C36: =COUNTIFS(Trip_Data!$C$2:$C$51,A36,Trip_Data!$H$2:$H$51,"Late") -> 1 | D36: =C36/B36 -> 0.25 | H36: 44973 | I36: =SUMIFS(Trip_Data!$F$2:$F$51,Trip_Data!$I$2:$I$51,H36) -> 3209 | J36: =SUMIFS(Trip_Data!$J$2:$J$51,Trip_Data!$I$2:$I$51,H36) -> 223.52 | K36: =I36/J36 -> 14.356657
A37: D09 | B37: =COUNTIFS(Trip_Data!$C$2:$C$51,A37) -> 4 | C37: =COUNTIFS(Trip_Data!$C$2:$C$51,A37,Trip_Data!$H$2:$H$51,"Late") -> 1 | D37: =C37/B37 -> 0.25 | H37: 44974 | I37: =SUMIFS(Trip_Data!$F$2:$F$51,Trip_Data!$I$2:$I$51,H37) -> 2466 | J37: =SUMIFS(Trip_Data!$J$2:$J$51,Trip_Data!$I$2:$I$51,H37) -> 271.3 | K37: =I37/J37 -> 9.0895687
A38: D10 | B38: =COUNTIFS(Trip_Data!$C$2:$C$51,A38) -> 6 | C38: =COUNTIFS(Trip_Data!$C$2:$C$51,A38,Trip_Data!$H$2:$H$51,"Late") -> 2 | D38: =C38/B38 -> 0.33333333 | H38: 44975 | I38: =SUMIFS(Trip_Data!$F$2:$F$51,Trip_Data!$I$2:$I$51,H38) -> 1624 | J38: =SUMIFS(Trip_Data!$J$2:$J$51,Trip_Data!$I$2:$I$51,H38) -> 158.47 | K38: =I38/J38 -> 10.247996
H39: 44977 | I39: =SUMIFS(Trip_Data!$F$2:$F$51,Trip_Data!$I$2:$I$51,H39) -> 1903 | J39: =SUMIFS(Trip_Data!$J$2:$J$51,Trip_Data!$I$2:$I$51,H39) -> 151.18 | K39: =I39/J39 -> 12.587644
A40: Late % by Distance Band (manual "key influencer" check) | H40: 44978 | I40: =SUMIFS(Trip_Data!$F$2:$F$51,Trip_Data!$I$2:$I$51,H40) -> 1727 | J40: =SUMIFS(Trip_Data!$J$2:$J$51,Trip_Data!$I$2:$I$51,H40) -> 161.33 | K40: =I40/J40 -> 10.704767
A41: Band | B41: Min km | C41: Max km | D41: Trips | E41: Late Trips | F41: Late % | H41: 44980 | I41: =SUMIFS(Trip_Data!$F$2:$F$51,Trip_Data!$I$2:$I$51,H41) -> 186 | J41: =SUMIFS(Trip_Data!$J$2:$J$51,Trip_Data!$I$2:$I$51,H41) -> 16.22 | K41: =I41/J41 -> 11.467324
...

Sheet Trip_Data
A1: Trip_ID | B1: Vehicle_ID | C1: Driver_ID | D1: Origin | E1: Destination | F1: Distance_km | G1: Fuel_Consumed_L | H1: Delivery_Status | I1: Delivery_Date | J1: Fuel_Clean_L | K1: Fuel_Imputed? | L1: Vehicle_Type | M1: Maintenance_Cost | N1: Fuel_Efficiency_km_per_L | O1: Cost_per_km | P1: On_Time_Flag
A2: T001 | B2: V04 | C2: D01 | D2: Delhi | E2: Pune | F2: 1173 | G2: 108.42 | H2: On-Time | I2: 44953 | J2: =IF(G2="",Assumptions!$B$3,G2) -> 108.42 | K2: =IF(G2="","Yes","No") -> No | L2: =INDEX(Vehicle_Master!$B$2:$B$8,MATCH(B2,Vehicle_Master!$A$2:$A$8,0)) -> Mini-Truck | M2: =INDEX(Vehicle_Master!$D$2:$D$8,MATCH(B2,Vehicle_Master!$A$2:$A$8,0)) -> 9033 | N2: =F2/J2 -> 10.819037 | O2: =(Assumptions!$B$4+M2)/F2 -> 7.7860188 | P2: =IF(H2="On-Time",1,0) -> 1
A3: T002 | B3: V06 | C3: D08 | D3: Mumbai | E3: Bangalore | F3: 1727 | G3: 161.33 | H3: On-Time | I3: 44978 | J3: =IF(G3="",Assumptions!$B$3,G3) -> 161.33 | K3: =IF(G3="","Yes","No") -> No | L3: =INDEX(Vehicle_Master!$B$2:$B$8,MATCH(B3,Vehicle_Master!$A$2:$A$8,0)) -> Van | M3: =INDEX(Vehicle_Master!$D$2:$D$8,MATCH(B3,Vehicle_Master!$A$2:$A$8,0)) -> 5914 | N3: =F3/J3 -> 10.704767 | O3: =(Assumptions!$B$4+M3)/F3 -> 3.4823393 | P3: =IF(H3="On-Time",1,0) -> 1
A4: T003 | B4: V06 | C4: D08 | D4: Mumbai | E4: Pune | F4: 1459 | G4: 154.7 | H4: On-Time | I4: 44974 | J4: =IF(G4="",Assumptions!$B$3,G4) -> 154.7 | K4: =IF(G4="","Yes","No") -> No | L4: =INDEX(Vehicle_Master!$B$2:$B$8,MATCH(B4,Vehicle_Master!$A$2:$A$8,0)) -> Van | M4: =INDEX(Vehicle_Master!$D$2:$D$8,MATCH(B4,Vehicle_Master!$A$2:$A$8,0)) -> 5914 | N4: =F4/J4 -> 9.4311571 | O4: =(Assumptions!$B$4+M4)/F4 -> 4.1220014 | P4: =IF(H4="On-Time",1,0) -> 1
A5: T004 | B5: V04 | C5: D09 | D5: Hyderabad | E5: Pune | F5: 382 | G5: 26.6 | H5: On-Time | I5: 44975 | J5: =IF(G5="",Assumptions!$B$3,G5) -> 26.6 | K5: =IF(G5="","Yes","No") -> No | L5: =INDEX(Vehicle_Master!$B$2:$B$8,MATCH(B5,Vehicle_Master!$A$2:$A$8,0)) -> Mini-Truck | M5: =INDEX(Vehicle_Master!$D$2:$D$8,MATCH(B5,Vehicle_Master!$A$2:$A$8,0)) -> 9033 | N5: =F5/J5 -> 14.360902 | O5: =(Assumptions!$B$4+M5)/F5 -> 23.908377 | P5: =IF(H5="On-Time",1,0) -> 1
A6: T005 | B6: V06 | C6: D08 | D6: Pune | E6: Mumbai | F6: 398 | G6: 33.2 | H6: On-Time | I6: 44972 | J6: =IF(G6="",Assumptions!$B$3,G6) -> 33.2 | K6: =IF(G6="","Yes","No") -> No | L6: =INDEX(Vehicle_Master!$B$2:$B$8,MATCH(B6,Vehicle_Master!$A$2:$A$8,0)) -> Van | M6: =INDEX(Vehicle_Master!$D$2:$D$8,MATCH(B6,Vehicle_Master!$A$2:$A$8,0)) -> 5914 | N6: =F6/J6 -> 11.987952 | O6: =(Assumptions!$B$4+M6)/F6 -> 15.110553 | P6: =IF(H6="On-Time",1,0) -> 1
A7: T006 | B7: V06 | C7: D07 | D7: Chennai | E7: Mumbai | F7: 1275 | G7: 85.04 | H7: Late | I7: 44982 | J7: =IF(G7="",Assumptions!$B$3,G7) -> 85.04 | K7: =IF(G7="","Yes","No") -> No | L7: =INDEX(Vehicle_Master!$B$2:$B$8,MATCH(B7,Vehicle_Master!$A$2:$A$8,0)) -> Van | M7: =INDEX(Vehicle_Master!$D$2:$D$8,MATCH(B7,Vehicle_Master!$A$2:$A$8,0)) -> 5914 | N7: =F7/J7 -> 14.992944 | O7: =(Assumptions!$B$4+M7)/F7 -> 4.7168627 | P7: =IF(H7="On-Time",1,0) -> 0
A8: T007 | B8: V07 | C8: D03 | D8: Chennai | E8: Kolkata | F8: 752 | G8: 58.08 | H8: On-Time | I8: 44945 | J8: =IF(G8="",Assumptions!$B$3,G8) -> 58.08 | K8: =IF(G8="","Yes","No") -> No | L8: =INDEX(Vehicle_Master!$B$2:$B$8,MATCH(B8,Vehicle_Master!$A$2:$A$8,0)) -> Van | M8: =INDEX(Vehicle_Master!$D$2:$D$8,MATCH(B8,Vehicle_Master!$A$2:$A$8,0)) -> 12837 | N8: =F8/J8 -> 12.947658 | O8: =(Assumptions!$B$4+M8)/F8 -> 17.203457 | P8: =IF(H8="On-Time",1,0) -> 1
A9: T008 | B9: V02 | C9: D10 | D9: Delhi | E9: Pune | F9: 74 | G9: 5.24 | H9: On-Time | I9: 44927 | J9: =IF(G9="",Assumptions!$B$3,G9) -> 5.24 | K9: =IF(G9="","Yes","No") -> No | L9: =INDEX(Vehicle_Master!$B$2:$B$8,MATCH(B9,Vehicle_Master!$A$2:$A$8,0)) -> Truck | M9: =INDEX(Vehicle_Master!$D$2:$D$8,MATCH(B9,Vehicle_Master!$A$2:$A$8,0)) -> 6776 | N9: =F9/J9 -> 14.122137 | O9: =(Assumptions!$B$4+M9)/F9 -> 92.918919 | P9: =IF(H9="On-Time",1,0) -> 1
A10: T009 | B10: V02 | C10: D07 | D10: Delhi | E10: Hyderabad | F10: 186 | G10: 16.22 | H10: On-Time | I10: 44980 | J10: =IF(G10="",Assumptions!$B$3,G10) -> 16.22 | K10: =IF(G10="","Yes","No") -> No | L10: =INDEX(Vehicle_Master!$B$2:$B$8,MATCH(B10,Vehicle_Master!$A$2:$A$8,0)) -> Truck | M10: =INDEX(Vehicle_Master!$D$2:$D$8,MATCH(B10,Vehicle_Master!$A$2:$A$8,0)) -> 6776 | N10: =F10/J10 -> 11.467324 | O10: =(Assumptions!$B$4+M10)/F10 -> 36.967742 | P10: =IF(H10="On-Time",1,0) -> 1
A11: T010 | B11: V02 | C11: D02 | D11: Bangalore | E11: Hyderabad | F11: 1375 | G11: 105.21 | H11: Late | I11: 44959 | J11: =IF(G11="",Assumptions!$B$3,G11) -> 105.21 | K11: =IF(G11="","Yes","No") -> No | L11: =INDEX(Vehicle_Master!$B$2:$B$8,MATCH(B11,Vehicle_Master!$A$2:$A$8,0)) -> Truck | M11: =INDEX(Vehicle_Master!$D$2:$D$8,MATCH(B11,Vehicle_Master!$A$2:$A$8,0)) -> 6776 | N11: =F11/J11 -> 13.0691 | O11: =(Assumptions!$B$4+M11)/F11 -> 5.0007273 | P11: =IF(H11="On-Time",1,0) -> 0
A12: T011 | B12: V06 | C12: D03 | D12: Kolkata | E12: Hyderabad | F12: 419 | G12: 31.17 | H12: On-Time | I12: 44947 | J12: =IF(G12="",Assumptions!$B$3,G12) -> 31.17 | K12: =IF(G12="","Yes","No") -> No | L12: =INDEX(Vehicle_Master!$B$2:$B$8,MATCH(B12,Vehicle_Master!$A$2:$A$8,0)) -> Van | M12: =INDEX(Vehicle_Master!$D$2:$D$8,MATCH(B12,Vehicle_Master!$A$2:$A$8,0)) -> 5914 | N12: =F12/J12 -> 13.442413 | O12: =(Assumptions!$B$4+M12)/F12 -> 14.353222 | P12: =IF(H12="On-Time",1,0) -> 1
A13: T012 | B13: V06 | C13: D01 | D13: Kolkata | E13: Delhi | F13: 751 | G13: 51.77 | H13: On-Time | I13: 44972 | J13: =IF(G13="",Assumptions!$B$3,G13) -> 51.77 | K13: =IF(G13="","Yes","No") -> No | L13: =INDEX(Vehicle_Master!$B$2:$B$8,MATCH(B13,Vehicle_Master!$A$2:$A$8,0)) -> Van | M13: =INDEX(Vehicle_Master!$D$2:$D$8,MATCH(B13,Vehicle_Master!$A$2:$A$8,0)) -> 5914 | N13: =F13/J13 -> 14.506471 | O13: =(Assumptions!$B$4+M13)/F13 -> 8.0079893 | P13: =IF(H13="On-Time",1,0) -> 1
... A16: T015 | B16: V05 | C16: D06 | D16: Kolkata | E16: Mumbai | F16: 1956 | G16: 179.88 | H16: On-Time | I16: 44947 | J16: =IF(G16="",Assumptions!$B$3,G16) -> 179.88 | K16: =IF(G16="","Yes","No") -> No | L16: =INDEX(Vehicle_Master!$B$2:$B$8,MATCH(B16,Vehicle_Master!$A$2:$A$8,0)) -> Truck | M16: =INDEX(Vehicle_Master!$D$2:$D$8,MATCH(B16,Vehicle_Master!$A$2:$A$8,0)) -> 17751 | N16: =F16/J16 -> 10.873916 | O16: =(Assumptions!$B$4+M16)/F16 -> 9.1262781 | P16: =IF(H16="On-Time",1,0) -> 1
A17: T016 | B17: V05 | C17: D06 | D17: Bangalore | E17: Mumbai | F17: 858 | H17: Late | I17: 44944 | J17: =IF(G17="",Assumptions!$B$3,G17) -> 91.882979 | K17: =IF(G17="","Yes","No") -> Yes | L17: =INDEX(Vehicle_Master!$B$2:$B$8,MATCH(B17,Vehicle_Master!$A$2:$A$8,0)) -> Truck | M17: =INDEX(Vehicle_Master!$D$2:$D$8,MATCH(B17,Vehicle_Master!$A$2:$A$8,0)) -> 17751 | N17: =F17/J17 -> 9.3379646 | O17: =(Assumptions!$B$4+M17)/F17 -> 20.805361 | P17: =IF(H17="On-Time",1,0) -> 0
A18: T017 | B18: V07 | C18: D07 | D18: Pune | E18: Kolkata | F18: 1269 | G18: 102.91 | H18: On-Time | I18: 44942 | J18: =IF(G18="",Assumptions!$B$3,G18) -> 102.91 | K18: =IF(G18="","Yes","No") -> No | L18: =INDEX(Vehicle_Master!$B$2:$B$8,MATCH(B18,Vehicle_Master!$A$2:$A$8,0)) -> Van | M18: =INDEX(Vehicle_Master!$D$2:$D$8,MATCH(B18,Vehicle_Master!$A$2:$A$8,0)) -> 12837 | N18: =F18/J18 -> 12.331163 | O18: =(Assumptions!$B$4+M18)/F18 -> 10.194641 | P18: =IF(H18="On-Time",1,0) -> 1
A19: T018 | B19: V07 | C19: D10 | D19: Pune | E19: Delhi | F19: 1565 | G19: 107.23 | H19: On-Time | I19: 44969 | J19: =IF(G19="",Assumptions!$B$3,G19) -> 107.23 | K19: =IF(G19="","Yes","No") -> No | L19: =INDEX(Vehicle_Master!$B$2:$B$8,MATCH(B19,Vehicle_Master!$A$2:$A$8,0)) -> Van | M19: =INDEX(Vehicle_Master!$D$2:$D$8,MATCH(B19,Vehicle_Master!$A$2:$A$8,0)) -> 12837 | N19: =F19/J19 -> 14.594796 | O19: =(Assumptions!$B$4+M19)/F19 -> 8.2664537 | P19: =IF(H19="On-Time",1,0) -> 1
A20: T019 | B20: V07 | C20: D10 | D20: Hyderabad | E20: Pune | F20: 1796 | G20: 155.52 | H20: On-Time | I20: 44985 | J20: =IF(G20="",Assumptions!$B$3,G20) -> 155.52 | K20: =IF(G20="","Yes","No") -> No | L20: =INDEX(Vehicle_Master!$B$2:$B$8,MATCH(B20,Vehicle_Master!$A$2:$A$8,0)) -> Van | M20: =INDEX(Vehicle_Master!$D$2:$D$8,MATCH(B20,Vehicle_Master!$A$2:$A$8,0)) -> 12837 | N20: =F20/J20 -> 11.548354 | O20: =(Assumptions!$B$4+M20)/F20 -> 7.2032294 | P20: =IF(H20="On-Time",1,0) -> 1
A21: T020 | B21: V04 | C21: D02 | D21: Mumbai | E21: Bangalore | F21: 1640 | G21: 148.87 | H21: On-Time | I21: 44932 | J21: =IF(G21="",Assumptions!$B$3,G21) -> 148.87 | K21: =IF(G21="","Yes","No") -> No | L21: =INDEX(Vehicle_Master!$B$2:$B$8,MATCH(B21,Vehicle_Master!$A$2:$A$8,0)) -> Mini-Truck | M21: =INDEX(Vehicle_Master!$D$2:$D$8,MATCH(B21,Vehicle_Master!$A$2:$A$8,0)) -> 9033 | N21: =F21/J21 -> 11.016323 | O21: =(Assumptions!$B$4+M21)/F21 -> 5.5689024 | P21: =IF(H21="On-Time",1,0) -> 1
A22: T021 | B22: V07 | C22: D07 | D22: Delhi | E22: Mumbai | F22: 446 | G22: 31.98 | H22: Late | I22: 44937 | J22: =IF(G22="",Assumptions!$B$3,G22) -> 31.98 | K22: =IF(G22="","Yes","No") -> No | L22: =INDEX(Vehicle_Master!$B$2:$B$8,MATCH(B22,Vehicle_Master!$A$2:$A$8,0)) -> Van | M22: =INDEX(Vehicle_Master!$D$2:$D$8,MATCH(B22,Vehicle_Master!$A$2:$A$8,0)) -> 12837 | N22: =F22/J22 -> 13.946216 | O22: =(Assumptions!$B$4+M22)/F22 -> 29.006726 | P22: =IF(H22="On-Time",1,0) -> 0
A23: T022 | B23: V07 | C23: D09 | D23: Hyderabad | E23: Delhi | F23: 140 | G23: 11.44 | H23: On-Time | I23: 44964 | J23: =IF(G23="",Assumptions!$B$3,G23) -> 11.44 | K23: =IF(G23="","Yes","No") -> No | L23: =INDEX(Vehicle_Master!$B$2:$B$8,MATCH(B23,Vehicle_Master!$A$2:$A$8,0)) -> Van | M23: =INDEX(Vehicle_Master!$D$2:$D$8,MATCH(B23,Vehicle_Master!$A$2:$A$8,0)) -> 12837 | N23: =F23/J23 -> 12.237762 | O23: =(Assumptions!$B$4+M23)/F23 -> 92.407143 | P23: =IF(H23="On-Time",1,0) -> 1
A24: T023 | B24: V06 | C24: D04 | D24: Chennai | E24: Delhi | F24: 1729 | G24: 197.55 | H24: On-Time | I24: 44963 | J24: =IF(G24="",Assumptions!$B$3,G24) -> 197.55 | K24: =IF(G24="","Yes","No") -> No | L24: =INDEX(Vehicle_Master!$B$2:$B$8,MATCH(B24,Vehicle_Master!$A$2:$A$8,0)) -> Van | M24: =INDEX(Vehicle_Master!$D$2:$D$8,MATCH(B24,Vehicle_Master!$A$2:$A$8,0)) -> 5914 | N24: =F24/J24 -> 8.7522146 | O24: =(Assumptions!$B$4+M24)/F24 -> 3.4783112 | P24: =IF(H24="On-Time",1,0) -> 1
A25: T024 | B25: V04 | C25: D01 | D25: Kolkata | E25: Mumbai | F25: 1376 | G25: 96.63 | H25: On-Time | I25: 44971 | J25: =IF(G25="",Assumptions!$B$3,G25) -> 96.63 | K25: =IF(G25="","Yes","No") -> No | L25: =INDEX(Vehicle_Master!$B$2:$B$8,MATCH(B25,Vehicle_Master!$A$2:$A$8,0)) -> Mini-Truck | M25: =INDEX(Vehicle_Master!$D$2:$D$8,MATCH(B25,Vehicle_Master!$A$2:$A$8,0)) -> 9033 | N25: =F25/J25 -> 14.239884 | O25: =(Assumptions!$B$4+M25)/F25 -> 6.6373547 | P25: =IF(H25="On-Time",1,0) -> 1
A26: T025 | B26: V04 | C26: D02 | D26: Bangalore | E26: Chennai | F26: 1721 | G26: 120.65 | H26: Late | I26: 44963 | J26: =IF(G26="",Assumptions!$B$3,G26) -> 120.65 | K26: =IF(G26="","Yes","No") -> No | L26: =INDEX(Vehicle_Master!$B$2:$B$8,MATCH(B26,Vehicle_Master!$A$2:$A$8,0)) -> Mini-Truck | M26: =INDEX(Vehicle_Master!$D$2:$D$8,MATCH(B26,Vehicle_Master!$A$2:$A$8,0)) -> 9033 | N26: =F26/J26 -> 14.264401 | O26: =(Assumptions!$B$4+M26)/F26 -> 5.3067984 | P26: =IF(H26="On-Time",1,0) -> 0
A27: T026 | B27: V05 | C27: D04 | D27: Chennai | E27: Pune | F27: 1784 | H27: Late | I27: 44943 | J27: =IF(G27="",Assumptions!$B$3,G27) -> 91.882979 | K27: =IF(G27="","Yes","No") -> Yes | L27: =INDEX(Vehicle_Master!$B$2:$B$8,MATCH(B27,Vehicle_Master!$A$2:$A$8,0)) -> Truck | M27: =INDEX(Vehicle_Master!$D$2:$D$8,MATCH(B27,Vehicle_Master!$A$2:$A$8,0)) -> 17751 | N27: =F27/J27 -> 19.416001 | O27: =(Assumptions!$B$4+M27)/F27 -> 10.006166 | P27: =IF(H27="On-Time",1,0) -> 0
A28: T027 | B28: V06 | C28: D07 | D28: Pune | E28: Kolkata | F28: 1007 | G28: 116.6 | H28: Late | I28: 44974 | J28: =IF(G28="",Assumptions!$B$3,G28) -> 116.6 | K28: =IF(G28="","Yes","No") -> No | L28: =INDEX(Vehicle_Master!$B$2:$B$8,MATCH(B28,Vehicle_Master!$A$2:$A$8,0)) -> Van | M28: =INDEX(Vehicle_Master!$D$2:$D$8,MATCH(B28,Vehicle_Master!$A$2:$A$8,0)) -> 5914 | N28: =F28/J28 -> 8.6363636 | O28: =(Assumptions!$B$4+M28)/F28 -> 5.9721946 | P28: =IF(H28="On-Time",1,0) -> 0
A29: T028 | B29: V05 | C29: D06 | D29: Pune | E29: Bangalore | F29: 1903 | G29: 151.18 | H29: Late | I29: 44977 | J29: =IF(G29="",Assumptions!$B$3,G29) -> 151.18 | K29: =IF(G29="","Yes","No") -> No | L29: =INDEX(Vehicle_Master!$B$2:$B$8,MATCH(B29,Vehicle_Master!$A$2:$A$8,0)) -> Truck | M29: =INDEX(Vehicle_Master!$D$2:$D$8,MATCH(B29,Vehicle_Master!$A$2:$A$8,0)) -> 17751 | N29: =F29/J29 -> 12.587644 | O29: =(Assumptions!$B$4+M29)/F29 -> 9.3804519 | P29: =IF(H29="On-Time",1,0) -> 0
A30: T029 | B30: V01 | C30: D06 | D30: Mumbai | E30: Bangalore | F30: 1262 | G30: 100.72 | H30: On-Time | I30: 44954 | J30: =IF(G30="",Assumptions!$B$3,G30) -> 100.72 | K30: =IF(G30="","Yes","No") -> No | L30: =INDEX(Vehicle_Master!$B$2:$B$8,MATCH(B30,Vehicle_Master!$A$2:$A$8,0)) -> Van | M30: =INDEX(Vehicle_Master!$D$2:$D$8,MATCH(B30,Vehicle_Master!$A$2:$A$8,0)) -> 5633 | N30: =F30/J30 -> 12.529786 | O30: =(Assumptions!$B$4+M30)/F30 -> 4.5427892 | P30: =IF(H30="On-Time",1,0) -> 1
A31: T030 | B31: V02 | C31: D09 | D31: Kolkata | E31: Hyderabad | F31: 317 | G31: 28.83 | H31: On-Time | I31: 44985 | J31: =IF(G31="",Assumptions!$B$3,G31) -> 28.83 | K31: =IF(G31="","Yes","No") -> No | L31: =INDEX(Vehicle_Master!$B$2:$B$8,MATCH(B31,Vehicle_Master!$A$2:$A$8,0)) -> Truck | M31: =INDEX(Vehicle_Master!$D$2:$D$8,MATCH(B31,Vehicle_Master!$A$2:$A$8,0)) -> 6776 | N31: =F31/J31 -> 10.995491 | O31: =(Assumptions!$B$4+M31)/F31 -> 21.690852 | P31: =IF(H31="On-Time",1,0) -> 1
A32: T031 | B32: V05 | C32: D04 | D32: Hyderabad | E32: Delhi | F32: 1188 | G32: 92.84 | H32: On-Time | I32: 44960 | J32: =IF(G32="",Assumptions!$B$3,G32) -> 92.84 | K32: =IF(G32="","Yes","No") -> No | L32: =INDEX(Vehicle_Master!$B$2:$B$8,MATCH(B32,Vehicle_Master!$A$2:$A$8,0)) -> Truck | M32: =INDEX(Vehicle_Master!$D$2:$D$8,MATCH(B32,Vehicle_Master!$A$2:$A$8,0)) -> 17751 | N32: =F32/J32 -> 12.796209 | O32: =(Assumptions!$B$4+M32)/F32 -> 15.026094 | P32: =IF(H32="On-Time",1,0) -> 1
A33: T032 | B33: V01 | C33: D10 | D33: Hyderabad | E33: Kolkata | F33: 398 | G33: 43.89 | H33: Late | I33: 44962 | J33: =IF(G33="",Assumptions!$B$3,G33) -> 43.89 | K33: =IF(G33="","Yes","No") -> No | L33: =INDEX(Vehicle_Master!$B$2:$B$8,MATCH(B33,Vehicle_Master!$A$2:$A$8,0)) -> Van | M33: =INDEX(Vehicle_Master!$D$2:$D$8,MATCH(B33,Vehicle_Master!$A$2:$A$8,0)) -> 5633 | N33: =F33/J33 -> 9.0681249 | O33: =(Assumptions!$B$4+M33)/F33 -> 14.404523 | P33: =IF(H33="On-Time",1,0) -> 0
A34: T033 | B34: V05 | C34: D09 | D34: Hyderabad | E34: Chennai | F34: 385 | G34: 31.03 | H34: Late | I34: 44950 | J34: =IF(G34="",Assumptions!$B$3,G34) -> 31.03 | K34: =IF(G34="","Yes","No") -> No | L34: =INDEX(Vehicle_Master!$B$2:$B$8,MATCH(B34,Vehicle_Master!$A$2:$A$8,0)) -> Truck | M34: =INDEX(Vehicle_Master!$D$2:$D$8,MATCH(B34,Vehicle_Master!$A$2:$A$8,0)) -> 17751 | N34: =F34/J34 -> 12.407348 | O34: =(Assumptions!$B$4+M34)/F34 -> 46.366234 | P34: =IF(H34="On-Time",1,0) -> 0
A35: T034 | B35: V02 | C35: D10 | D35: Delhi | E35: Hyderabad | F35: 818 | G35: 94.24 | H35: Late | I35: 44975 | J35: =IF(G35="",Assumptions!$B$3,G35) -> 94.24 | K35: =IF(G35="","Yes","No") -> No | L35: =INDEX(Vehicle_Master!$B$2:$B$8,MATCH(B35,Vehicle_Master!$A$2:$A$8,0)) -> Truck | M35: =INDEX(Vehicle_Master!$D$2:$D$8,MATCH(B35,Vehicle_Master!$A$2:$A$8,0)) -> 6776 | N35: =F35/J35 -> 8.679966 | O35: =(Assumptions!$B$4+M35)/F35 -> 8.405868 | P35: =IF(H35="On-Time",1,0) -> 0
A36: T035 | B36: V04 | C36: D04 | D36: Delhi | E36: Kolkata | F36: 1806 | G36: 121.36 | H36: On-Time | I36: 44967 | J36: =IF(G36="",Assumptions!$B$3,G36) -> 121.36 | K36: =IF(G36="","Yes","No") -> No | L36: =INDEX(Vehicle_Master!$B$2:$B$8,MATCH(B36,Vehicle_Master!$A$2:$A$8,0)) -> Mini-Truck | M36: =INDEX(Vehicle_Master!$D$2:$D$8,MATCH(B36,Vehicle_Master!$A$2:$A$8,0)) -> 9033 | N36: =F36/J36 -> 14.881345 | O36: =(Assumptions!$B$4+M36)/F36 -> 5.0570321 | P36: =IF(H36="On-Time",1,0) -> 1
A37: T036 | B37: V02 | C37: D10 | D37: Delhi | E37: Pune | F37: 424 | G37: 37.63 | H37: On-Time | I37: 44975 | J37: =IF(G37="",Assumptions!$B$3,G37) -> 37.63 | K37: =IF(G37="","Yes","No") -> No | L37: =INDEX(Vehicle_Master!$B$2:$B$8,MATCH(B37,Vehicle_Master!$A$2:$A$8,0)) -> Truck | M37: =INDEX(Vehicle_Master!$D$2:$D$8,MATCH(B37,Vehicle_Master!$A$2:$A$8,0)) -> 6776 | N37: =F37/J37 -> 11.267606 | O37: =(Assumptions!$B$4+M37)/F37 -> 16.216981 | P37: =IF(H37="On-Time",1,0) -> 1
A38: T037 | B38: V06 | C38: D01 | D38: Delhi | E38: Bangalore | F38: 909 | G38: 70.4 | H38: On-Time | I38: 44944 | J38: =IF(G38="",Assumptions!$B$3,G38) -> 70.4 | K38: =IF(G38="","Yes","No") -> No | L38: =INDEX(Vehicle_Master!$B$2:$B$8,MATCH(B38,Vehicle_Master!$A$2:$A$8,0)) -> Van | M38: =INDEX(Vehicle_Master!$D$2:$D$8,MATCH(B38,Vehicle_Master!$A$2:$A$8,0)) -> 5914 | N38: =F38/J38 -> 12.911932 | O38: =(Assumptions!$B$4+M38)/F38 -> 6.6160616 | P38: =IF(H38="On-Time",1,0) -> 1
A39: T038 | B39: V03 | C39: D06 | D39: Bangalore | E39: Mumbai | F39: 1404 | G39: 151.36 | H39: Late | I39: 44981 | J39: =IF(G39="",Assumptions!$B$3,G39) -> 151.36 | K39: =IF(G39="","Yes","No") -> No | L39: =INDEX(Vehicle_Master!$B$2:$B$8,MATCH(B39,Vehicle_Master!$A$2:$A$8,0)) -> Truck | M39: =INDEX(Vehicle_Master!$D$2:$D$8,MATCH(B39,Vehicle_Master!$A$2:$A$8,0)) -> 18031 | N39: =F39/J39 -> 9.2758985 | O39: =(Assumptions!$B$4+M39)/F39 -> 12.913818 | P39: =IF(H39="On-Time",1,0) -> 0
... A44: T043 | B44: V06 | C44: D06 | D44: Hyderabad | E44: Bangalore | F44: 116 | G44: 8.71 | H44: Late | I44: 44932 | J44: =IF(G44="",Assumptions!$B$3,G44) -> 8.71 | K44: =IF(G44="","Yes","No") -> No | L44: =INDEX(Vehicle_Master!$B$2:$B$8,MATCH(B44,Vehicle_Master!$A$2:$A$8,0)) -> Van | M44: =INDEX(Vehicle_Master!$D$2:$D$8,MATCH(B44,Vehicle_Master!$A$2:$A$8,0)) -> 5914 | N44: =F44/J44 -> 13.318025 | O44: =(Assumptions!$B$4+M44)/F44 -> 51.844828 | P44: =IF(H44="On-Time",1,0) -> 0
A45: T044 | B45: V04 | C45: D07 | D45: Delhi | E45: Mumbai | F45: 1259 | H45: Late | I45: 44955 | J45: =IF(G45="",Assumptions!$B$3,G45) -> 91.882979 | K45: =IF(G45="","Yes","No") -> Yes | L45: =INDEX(Vehicle_Master!$B$2:$B$8,MATCH(B45,Vehicle_Master!$A$2:$A$8,0)) -> Mini-Truck | M45: =INDEX(Vehicle_Master!$D$2:$D$8,MATCH(B45,Vehicle_Master!$A$2:$A$8,0)) -> 9033 | N45: =F45/J45 -> 13.702211 | O45: =(Assumptions!$B$4+M45)/F45 -> 7.25417 | P45: =IF(H45="On-Time",1,0) -> 0
A46: T045 | B46: V02 | C46: D03 | D46: Kolkata | E46: Chennai | F46: 1803 | G46: 211.34 | H46: On-Time | I46: 44970 | J46: =IF(G46="",Assumptions!$B$3,G46) -> 211.34 | K46: =IF(G46="","Yes","No") -> No | L46: =INDEX(Vehicle_Master!$B$2:$B$8,MATCH(B46,Vehicle_Master!$A$2:$A$8,0)) -> Truck | M46: =INDEX(Vehicle_Master!$D$2:$D$8,MATCH(B46,Vehicle_Master!$A$2:$A$8,0)) -> 6776 | N46: =F46/J46 -> 8.5312766 | O46: =(Assumptions!$B$4+M46)/F46 -> 3.8136439 | P46: =IF(H46="On-Time",1,0) -> 1
...

Sheet Vehicle_Master
A1: Vehicle_ID | B1: Vehicle_Type | C1: Capacity_kg | D1: Maintenance_Cost
A2: V01 | B2: Van | C2: 8424 | D2: 5633
A3: V02 | B3: Truck | C3: 1970 | D3: 6776
A4: V03 | B4: Truck | C4: 1207 | D4: 18031
A5: V04 | B5: Mini-Truck | C5: 8803 | D5: 9033
A6: V05 | B6: Truck | C6: 9941 | D6: 17751
A7: V06 | B7: Van | C7: 6053 | D7: 5914
A8: V07 | B8: Van | C8: 2598 | D8: 12837

Sheet Assumptions
A1: Assumptions & Inputs
A2: Item | B2: Value | C2: Note
A3: Mean Fuel_Consumed_L (for imputation) | B3: =AVERAGE(Trip_Data!G2:G51) -> 91.882979 | C3: Average of the 47 trips that have fuel recorded (blanks ignored). Used to fill the 3 missing values.
A4: Fuel cost per trip | B4: 100 | C4: Given in the assignment ("fuel cost = 100"). Treated as a flat 100 per trip.
